// Promises 

const empleados = [
    {
        id: 1,
        nombre: "Omar"
    },
    {
        id: 2,
        nombre: "DÃ­az"
    },
    {
        id: 3,
        nombre: "Zaki"
    },
    {
        id: 4,
        nombre: "Foxo"
    }
];

const salarios = [
    {
        id_empleado: 1,
        salario: 1000
    },
    {
        id_empleado: 2,
        salario: 1500
    },
    {
        id_empleado: 3,
        salario: 2000
    }
];

// Buscar Empleado
const getEmpleado = (id) => {
    return promise = new Promise( (resolve, reject) => {
        const empleado = empleados.find( (e) => e.id === id )?.nombre;

        (empleado) ? resolve(empleado) : reject(`El empleado con el ID: ${id} no existe`);
    });
};

// Buscar Salario
const getSalario = (id) => {
    return promise = new Promise( (resolve, reject) => {
        const salario = salarios.find( (s) => s.id_empleado === id )?.salario;

        (salario) ? resolve(salario) : reject(`El empleado con el ID: ${id} no tiene un salario asignado`);
    });
};

// Consulta Empleado - Salario
let id = 3;

// getEmpleado(id)
//     .then((empleado) => { console.log(empleado) })
//     .catch((err) => { console.log(err); });

// getSalario(id)
//     .then((salario) => { console.log(salario) })
//     .catch((err) => { console.log(err); });

// getEmpleado(id)
//     .then((empleado) => 
//         getSalario(id)
//             .then((salario) => { console.log(`El empleado ${empleado} gana ${salario}`) })
//             .catch((err) => { console.log(err) })
//     )
//     .catch((err) => { console.log(err) });

// getEmpleado(id).then( (empleado) => {
//     emp = empleado;
//     return getSalario(id); }).then( (salario) => {
//         console.log(`El empleado ${emp} gana ${salario}`);
// }).catch( (err) => console.log(err));

getInfoUsuario = async (id) => {
    const empleado = await getEmpleado(id);
    const salario = await getSalario(id);
    return `El empleado ${empleado} gana ${salario}`;
};

getInfoUsuario(id)
    .then( usuario => console.log(usuario))
    .catch( err => console.log(err));